<?xml version="1.0" encoding="UTF-8"?>
<testsuite name="Failed Test"
           tests="1"
           failures="1"
           errors="0"
           skipped="0"
           time="0,001">
  <properties />
            <testcase name="failTest" time="0,001" classname="FailedTest">
                <failure type="java.lang.AssertionError"
                  message="did not expect to find [java.lang.Object@184f1538] but found [java.lang.Object@39e007b]"
              >
<![CDATA[java.lang.AssertionError: did not expect to find [java.lang.Object@184f1538] but found [java.lang.Object@39e007b]
  org.testng.Assert.fail(Assert.java:97)
  org.testng.Assert.failNotEquals(Assert.java:969)
  org.testng.Assert.assertEqualsImpl(Assert.java:136)
  org.testng.Assert.assertEquals(Assert.java:118)
  org.testng.Assert.assertEquals(Assert.java:563)
  FailedTest.failTest(FailedTest.java:7)
  sun.reflect.NativeMethodAccessorImpl.invoke0(Native Method)
  sun.reflect.NativeMethodAccessorImpl.invoke(NativeMethodAccessorImpl.java:62)
  sun.reflect.DelegatingMethodAccessorImpl.invoke(DelegatingMethodAccessorImpl.java:43)
  java.lang.reflect.Method.invoke(Method.java:498)
  org.testng.internal.MethodInvocationHelper.invokeMethod(MethodInvocationHelper.java:131)
  org.testng.internal.Invoker.invokeMethod(Invoker.java:658)
  org.testng.internal.Invoker.invokeTestMethod(Invoker.java:792)
  org.testng.internal.Invoker.invokeTestMethods(Invoker.java:1103)
  org.testng.internal.TestMethodWorker.invokeTestMethods(TestMethodWorker.java:140)
  org.testng.internal.TestMethodWorker.run(TestMethodWorker.java:122)
  java.util.concurrent.ThreadPoolExecutor.runWorker(ThreadPoolExecutor.java:1149)
  java.util.concurrent.ThreadPoolExecutor$Worker.run(ThreadPoolExecutor.java:624)
  java.lang.Thread.run(Thread.java:748)
]]>
      </failure>

          </testcase>
  
  
  
</testsuite>
